Workbook

Sheet Inventory_Data
A1: Item_Code | B1: Item_Name | C1: Unit_Price | D1: Annual_Usage_Qty | E1: Jan | F1: Feb | G1: Mar | H1: Apr | I1: May | J1: Jun | K1: Jul | L1: Aug | M1: Sep | N1: Oct | O1: Nov | P1: Dec | Q1: Transactions | R1: Last_Movement_Date | S1: Annual_Value | T1: Percentage Contribution | U1: Cumulative % | V1: ABC Classification | W1: Mean Demand | X1: Standard Deviation | Y1: Coefficient of Variation | Z1: XYZ Classification | AA1: FSN Classification
A2: SKU068 | B2: Safety Helmet | C2: 4858.61 | D2: 4297 | E2: 442 | F2: 183 | G2: 459 | H2: 217 | I2: 348 | J2: 460 | K2: 229 | L2: 490 | M2: 449 | N2: 375 | O2: 336 | P2: 309 | Q2: 64 | R2: 2024-06-17 | S2: =C2*D2 -> 20877447 | T2: =S2/$S$103 -> 0.026119651 | U2: =SUM($T$2:T3) -> 0.051239762 | V2: =IF(U2<=0.8,"A",IF(U2<=0.95,"B","C")) -> A | W2: =AVERAGE(E2:P2) -> 358.08333 | X2: =_xlfn.STDEV.P(E2:P2) -> 101.56563 | Y2: =X2/W2 -> 0.28363684 | Z2: =IF(Y2<=0.2,"X",IF(Y2<=0.5,"Y","Z")) -> Y | AA2: =IF(Q2>=$Q$105,"F", IF(Q2<=$Q$106,"N", "S")) -> N
A3: SKU003 | B3: Mask | C3: 4999.63 | D3: 4016 | E3: 262 | F3: 354 | G3: 471 | H3: 448 | I3: 146 | J3: 375 | K3: 279 | L3: 413 | M3: 383 | N3: 379 | O3: 141 | P3: 365 | Q3: 69 | R3: 2025-06-20 | S3: =C3*D3 -> 20078514 | T3: =S3/$S$103 -> 0.025120111 | U3: =SUM($T$2:T4) -> 0.072970816 | V3: =IF(U3<=0.8,"A",IF(U3<=0.95,"B","C")) -> A | W3: =AVERAGE(E3:P3) -> 334.66667 | X3: =_xlfn.STDEV.P(E3:P3) -> 102.57951 | Y3: =X3/W3 -> 0.30651248 | Z3: =IF(Y3<=0.2,"X",IF(Y3<=0.5,"Y","Z")) -> Y | AA3: =IF(Q3>=$Q$105,"F", IF(Q3<=$Q$106,"N", "S")) -> S
A4: SKU040 | B4: Circuit Breaker | C4: 4636.85 | D4: 3746 | E4: 481 | F4: 372 | G4: 41 | H4: 361 | I4: 428 | J4: 471 | K4: 85 | L4: 237 | M4: 455 | N4: 165 | O4: 237 | P4: 413 | Q4: 69 | R4: 2026-01-19 | S4: =C4*D4 -> 17369640 | T4: =S4/$S$103 -> 0.021731054 | U4: =SUM($T$2:T5) -> 0.093974889 | V4: =IF(U4<=0.8,"A",IF(U4<=0.95,"B","C")) -> A | W4: =AVERAGE(E4:P4) -> 312.16667 | X4: =_xlfn.STDEV.P(E4:P4) -> 147.69836 | Y4: =X4/W4 -> 0.47313943 | Z4: =IF(Y4<=0.2,"X",IF(Y4<=0.5,"Y","Z")) -> Y | AA4: =IF(Q4>=$Q$105,"F", IF(Q4<=$Q$106,"N", "S")) -> S
A5: SKU023 | B5: Cleaning Chemical | C5: 4723.85 | D5: 3554 | E5: 180 | F5: 390 | G5: 409 | H5: 370 | I5: 340 | J5: 352 | K5: 157 | L5: 272 | M5: 311 | N5: 303 | O5: 468 | P5: 2 | Q5: 230 | R5: 2026-02-05 | S5: =C5*D5 -> 16788563 | T5: =S5/$S$103 -> 0.021004072 | U5: =SUM($T$2:T6) -> 0.1144223 | V5: =IF(U5<=0.8,"A",IF(U5<=0.95,"B","C")) -> A | W5: =AVERAGE(E5:P5) -> 296.16667 | X5: =_xlfn.STDEV.P(E5:P5) -> 123.08522 | Y5: =X5/W5 -> 0.41559445 | Z5: =IF(Y5<=0.2,"X",IF(Y5<=0.5,"Y","Z")) -> Y | AA5: =IF(Q5>=$Q$105,"F", IF(Q5<=$Q$106,"N", "S")) -> F
A6: SKU049 | B6: Hydraulic Hose | C6: 4841.12 | D6: 3376 | E6: 105 | F6: 269 | G6: 280 | H6: 450 | I6: 93 | J6: 489 | K6: 219 | L6: 240 | M6: 260 | N6: 419 | O6: 293 | P6: 259 | Q6: 69 | R6: 2024-09-29 | S6: =C6*D6 -> 16343621 | T6: =S6/$S$103 -> 0.020447408 | U6: =SUM($T$2:T7) -> 0.1346979 | V6: =IF(U6<=0.8,"A",IF(U6<=0.95,"B","C")) -> A | W6: =AVERAGE(E6:P6) -> 281.33333 | X6: =_xlfn.STDEV.P(E6:P6) -> 116.87838 | Y6: =X6/W6 -> 0.41544448 | Z6: =IF(Y6<=0.2,"X",IF(Y6<=0.5,"Y","Z")) -> Y | AA6: =IF(Q6>=$Q$105,"F", IF(Q6<=$Q$106,"N", "S")) -> S
A7: SKU030 | B7: Fuse | C7: 4325.14 | D7: 3747 | E7: 160 | F7: 302 | G7: 446 | H7: 307 | I7: 203 | J7: 28 | K7: 399 | L7: 180 | M7: 333 | N7: 405 | O7: 485 | P7: 499 | Q7: 0 | R7: 2025-04-17 | S7: =C7*D7 -> 16206300 | T7: =S7/$S$103 -> 0.020275606 | U7: =SUM($T$2:T8) -> 0.153904 | V7: =IF(U7<=0.8,"A",IF(U7<=0.95,"B","C")) -> A | W7: =AVERAGE(E7:P7) -> 312.25 | X7: =_xlfn.STDEV.P(E7:P7) -> 139.25464 | Y7: =X7/W7 -> 0.44597162 | Z7: =IF(Y7<=0.2,"X",IF(Y7<=0.5,"Y","Z")) -> Y | AA7: =IF(Q7>=$Q$105,"F", IF(Q7<=$Q$106,"N", "S")) -> N
A8: SKU010 | B8: Welding Rod | C8: 3804.57 | D8: 4035 | E8: 479 | F8: 415 | G8: 486 | H8: 321 | I8: 296 | J8: 261 | K8: 214 | L8: 423 | M8: 273 | N8: 201 | O8: 184 | P8: 482 | Q8: 126 | R8: 2024-10-13 | S8: =C8*D8 -> 15351440 | T8: =S8/$S$103 -> 0.019206096 | U8: =SUM($T$2:T9) -> 0.17268591 | V8: =IF(U8<=0.8,"A",IF(U8<=0.95,"B","C")) -> A | W8: =AVERAGE(E8:P8) -> 336.25 | X8: =_xlfn.STDEV.P(E8:P8) -> 110.19159 | Y8: =X8/W8 -> 0.32770734 | Z8: =IF(Y8<=0.2,"X",IF(Y8<=0.5,"Y","Z")) -> Y | AA8: =IF(Q8>=$Q$105,"F", IF(Q8<=$Q$106,"N", "S")) -> S
A9: SKU063 | B9: Hex Bolt | C9: 4481.31 | D9: 3350 | E9: 178 | F9: 487 | G9: 56 | H9: 300 | I9: 451 | J9: 205 | K9: 67 | L9: 449 | M9: 65 | N9: 255 | O9: 426 | P9: 411 | Q9: 245 | R9: 2025-01-30 | S9: =C9*D9 -> 15012388 | T9: =S9/$S$103 -> 0.018781911 | U9: =SUM($T$2:T10) -> 0.1905993 | V9: =IF(U9<=0.8,"A",IF(U9<=0.95,"B","C")) -> A | W9: =AVERAGE(E9:P9) -> 279.16667 | X9: =_xlfn.STDEV.P(E9:P9) -> 157.57106 | Y9: =X9/W9 -> 0.56443365 | Z9: =IF(Y9<=0.2,"X",IF(Y9<=0.5,"Y","Z")) -> Z | AA9: =IF(Q9>=$Q$105,"F", IF(Q9<=$Q$106,"N", "S")) -> F
A10: SKU067 | B10: Pneumatic Cylinder | C10: 4775.91 | D10: 2998 | E10: 154 | F10: 493 | G10: 251 | H10: 73 | I10: 191 | J10: 7 | K10: 197 | L10: 181 | M10: 488 | N10: 300 | O10: 388 | P10: 275 | Q10: 242 | R10: 2025-03-19 | S10: =C10*D10 -> 14318178 | T10: =S10/$S$103 -> 0.017913388 | U10: =SUM($T$2:T11) -> 0.20826601 | V10: =IF(U10<=0.8,"A",IF(U10<=0.95,"B","C")) -> A | W10: =AVERAGE(E10:P10) -> 249.83333 | X10: =_xlfn.STDEV.P(E10:P10) -> 143.90612 | Y10: =X10/W10 -> 0.5760085 | Z10: =IF(Y10<=0.2,"X",IF(Y10<=0.5,"Y","Z")) -> Z | AA10: =IF(Q10>=$Q$105,"F", IF(Q10<=$Q$106,"N", "S")) -> F
A11: SKU048 | B11: V Belt | C11: 4859.26 | D11: 2906 | E11: 181 | F11: 405 | G11: 442 | H11: 461 | I11: 301 | J11: 310 | K11: 121 | L11: 83 | M11: 184 | N11: 296 | O11: 11 | P11: 111 | Q11: 77 | R11: 2024-09-18 | S11: =C11*D11 -> 14121010 | T11: =S11/$S$103 -> 0.017666712 | U11: =SUM($T$2:T12) -> 0.22585142 | V11: =IF(U11<=0.8,"A",IF(U11<=0.95,"B","C")) -> A | W11: =AVERAGE(E11:P11) -> 242.16667 | X11: =_xlfn.STDEV.P(E11:P11) -> 142.32582 | Y11: =X11/W11 -> 0.58771846 | Z11: =IF(Y11<=0.2,"X",IF(Y11<=0.5,"Y","Z")) -> Z | AA11: =IF(Q11>=$Q$105,"F", IF(Q11<=$Q$106,"N", "S")) -> S
A12: SKU046 | B12: Hex Bolt | C12: 3790.73 | D12: 3708 | E12: 430 | F12: 409 | G12: 300 | H12: 168 | I12: 348 | J12: 413 | K12: 447 | L12: 290 | M12: 238 | N12: 439 | O12: 156 | P12: 70 | Q12: 4 | R12: 2026-04-29 | S12: =C12*D12 -> 14056027 | T12: =S12/$S$103 -> 0.017585412 | U12: =SUM($T$2:T13) -> 0.24340028 | V12: =IF(U12<=0.8,"A",IF(U12<=0.95,"B","C")) -> A | W12: =AVERAGE(E12:P12) -> 309 | X12: =_xlfn.STDEV.P(E12:P12) -> 122.07102 | Y12: =X12/W12 -> 0.39505184 | Z12: =IF(Y12<=0.2,"X",IF(Y12<=0.5,"Y","Z")) -> Y | AA12: =IF(Q12>=$Q$105,"F", IF(Q12<=$Q$106,"N", "S")) -> N
A13: SKU026 | B13: Hydraulic Pump | C13: 4958.22 | D13: 2829 | E13: 406 | F13: 222 | G13: 117 | H13: 449 | I13: 79 | J13: 494 | K13: 135 | L13: 412 | M13: 319 | N13: 60 | O13: 122 | P13: 14 | Q13: 179 | R13: 2024-08-06 | S13: =C13*D13 -> 14026804 | T13: =S13/$S$103 -> 0.017548852 | U13: =SUM($T$2:T14) -> 0.26055213 | V13: =IF(U13<=0.8,"A",IF(U13<=0.95,"B","C")) -> A | W13: =AVERAGE(E13:P13) -> 235.75 | X13: =_xlfn.STDEV.P(E13:P13) -> 163.59509 | Y13: =X13/W13 -> 0.69393464 | Z13: =IF(Y13<=0.2,"X",IF(Y13<=0.5,"Y","Z")) -> Z | AA13: =IF(Q13>=$Q$105,"F", IF(Q13<=$Q$106,"N", "S")) -> S
... A101: SKU084 | B101: Relay | C101: 39.85 | D101: 3048 | E101: 376 | F101: 297 | G101: 219 | H101: 318 | I101: 271 | J101: 253 | K101: 228 | L101: 327 | M101: 230 | N101: 56 | O101: 462 | P101: 11 | Q101: 49 | R101: 2025-05-31 | S101: =C101*D101 -> 121462.8 | T101: =S101/$S$103 -> 0.00015196139 | U101: =SUM($T$2:T102) -> 1 | V101: =IF(U101<=0.8,"A",IF(U101<=0.95,"B","C")) -> C | W101: =AVERAGE(E101:P101) -> 254 | X101: =_xlfn.STDEV.P(E101:P101) -> 119.17844 | Y101: =X101/W101 -> 0.46920645 | Z101: =IF(Y101<=0.2,"X",IF(Y101<=0.5,"Y","Z")) -> Y | AA101: =IF(Q101>=$Q$105,"F", IF(Q101<=$Q$106,"N", "S")) -> N
S103: =SUM(S2:S101) -> 799300380
P105: 75th | Q105: =_xlfn.PERCENTILE.INC(Q2:Q101,0.75) -> 200
P106: 25th | Q106: =_xlfn.PERCENTILE.INC(Q3:Q102,0.25) -> 68.5

Sheet ABC Classification

Sheet XYZ Classification

Sheet ABC-FSN Interpretation
A1: Item_Code | B1: =IFERROR(__xludf.DUMMYFUNCTION("FILTER(Inventory_Data!V:V,Inventory_Data!V:V<>"""")"),"ABC Classification") -> ABC Classification | C1: =IFERROR(__xludf.DUMMYFUNCTION("FILTER(Inventory_Data!AA:AA,Inventory_Data!AA:AA<>"""")"),"FSN Classification") -> FSN Classification | D1: ABC-FSN | E1: Interpretation
A2: =IFERROR(__xludf.DUMMYFUNCTION("FILTER(Inventory_Data!A2:A1000,Inventory_Data!A2:A1000<>"""")"),"SKU068") -> SKU068 | B2: =IFERROR(__xludf.DUMMYFUNCTION("""COMPUTED_VALUE"""),"A") -> A | C2: =IFERROR(__xludf.DUMMYFUNCTION("""COMPUTED_VALUE"""),"N") -> N | D2: =B2&C2 -> AN | E2: =XLOOKUP(D2,$K$11:$K$19,$L$11:$L$19) -> Capital Blocked
A3: =IFERROR(__xludf.DUMMYFUNCTION("""COMPUTED_VALUE"""),"SKU003") -> SKU003 | B3: =IFERROR(__xludf.DUMMYFUNCTION("""COMPUTED_VALUE"""),"A") -> A | C3: =IFERROR(__xludf.DUMMYFUNCTION("""COMPUTED_VALUE"""),"S") -> S | D3: =B3&C3 -> AS | E3: =XLOOKUP(D3,$K$11:$K$19,$L$11:$L$19) -> Important Item
A4: =IFERROR(__xludf.DUMMYFUNCTION("""COMPUTED_VALUE"""),"SKU040") -> SKU040 | B4: =IFERROR(__xludf.DUMMYFUNCTION("""COMPUTED_VALUE"""),"A") -> A | C4: =IFERROR(__xludf.DUMMYFUNCTION("""COMPUTED_VALUE"""),"S") -> S | D4: =B4&C4 -> AS | E4: =XLOOKUP(D4,$K$11:$K$19,$L$11:$L$19) -> Important Item
A5: =IFERROR(__xludf.DUMMYFUNCTION("""COMPUTED_VALUE"""),"SKU023") -> SKU023 | B5: =IFERROR(__xludf.DUMMYFUNCTION("""COMPUTED_VALUE"""),"A") -> A | C5: =IFERROR(__xludf.DUMMYFUNCTION("""COMPUTED_VALUE"""),"F") -> F | D5: =B5&C5 -> AF | E5: =XLOOKUP(D5,$K$11:$K$19,$L$11:$L$19) -> Critical Item
A6: =IFERROR(__xludf.DUMMYFUNCTION("""COMPUTED_VALUE"""),"SKU049") -> SKU049 | B6: =IFERROR(__xludf.DUMMYFUNCTION("""COMPUTED_VALUE"""),"A") -> A | C6: =IFERROR(__xludf.DUMMYFUNCTION("""COMPUTED_VALUE"""),"S") -> S | D6: =B6&C6 -> AS | E6: =XLOOKUP(D6,$K$11:$K$19,$L$11:$L$19) -> Important Item
A7: =IFERROR(__xludf.DUMMYFUNCTION("""COMPUTED_VALUE"""),"SKU030") -> SKU030 | B7: =IFERROR(__xludf.DUMMYFUNCTION("""COMPUTED_VALUE"""),"A") -> A | C7: =IFERROR(__xludf.DUMMYFUNCTION("""COMPUTED_VALUE"""),"N") -> N | D7: =B7&C7 -> AN | E7: =XLOOKUP(D7,$K$11:$K$19,$L$11:$L$19) -> Capital Blocked
A8: =IFERROR(__xludf.DUMMYFUNCTION("""COMPUTED_VALUE"""),"SKU010") -> SKU010 | B8: =IFERROR(__xludf.DUMMYFUNCTION("""COMPUTED_VALUE"""),"A") -> A | C8: =IFERROR(__xludf.DUMMYFUNCTION("""COMPUTED_VALUE"""),"S") -> S | D8: =B8&C8 -> AS | E8: =XLOOKUP(D8,$K$11:$K$19,$L$11:$L$19) -> Important Item
A9: =IFERROR(__xludf.DUMMYFUNCTION("""COMPUTED_VALUE"""),"SKU063") -> SKU063 | B9: =IFERROR(__xludf.DUMMYFUNCTION("""COMPUTED_VALUE"""),"A") -> A | C9: =IFERROR(__xludf.DUMMYFUNCTION("""COMPUTED_VALUE"""),"F") -> F | D9: =B9&C9 -> AF | E9: =XLOOKUP(D9,$K$11:$K$19,$L$11:$L$19) -> Critical Item
A10: =IFERROR(__xludf.DUMMYFUNCTION("""COMPUTED_VALUE"""),"SKU067") -> SKU067 | B10: =IFERROR(__xludf.DUMMYFUNCTION("""COMPUTED_VALUE"""),"A") -> A | C10: =IFERROR(__xludf.DUMMYFUNCTION("""COMPUTED_VALUE"""),"F") -> F | D10: =B10&C10 -> AF | E10: =XLOOKUP(D10,$K$11:$K$19,$L$11:$L$19) -> Critical Item | K10: Category | L10: Meaning
A11: =IFERROR(__xludf.DUMMYFUNCTION("""COMPUTED_VALUE"""),"SKU048") -> SKU048 | B11: =IFERROR(__xludf.DUMMYFUNCTION("""COMPUTED_VALUE"""),"A") -> A | C11: =IFERROR(__xludf.DUMMYFUNCTION("""COMPUTED_VALUE"""),"S") -> S | D11: =B11&C11 -> AS | E11: =XLOOKUP(D11,$K$11:$K$19,$L$11:$L$19) -> Important Item | K11: AF | L11: Critical Item
A12: =IFERROR(__xludf.DUMMYFUNCTION("""COMPUTED_VALUE"""),"SKU046") -> SKU046 | B12: =IFERROR(__xludf.DUMMYFUNCTION("""COMPUTED_VALUE"""),"A") -> A | C12: =IFERROR(__xludf.DUMMYFUNCTION("""COMPUTED_VALUE"""),"N") -> N | D12: =B12&C12 -> AN | E12: =XLOOKUP(D12,$K$11:$K$19,$L$11:$L$19) -> Capital Blocked | K12: AS | L12: Important Item
A13: =IFERROR(__xludf.DUMMYFUNCTION("""COMPUTED_VALUE"""),"SKU026") -> SKU026 | B13: =IFERROR(__xludf.DUMMYFUNCTION("""COMPUTED_VALUE"""),"A") -> A | C13: =IFERROR(__xludf.DUMMYFUNCTION("""COMPUTED_VALUE"""),"S") -> S | D13: =B13&C13 -> AS | E13: =XLOOKUP(D13,$K$11:$K$19,$L$11:$L$19) -> Important Item | K13: AN | L13: Capital Blocked
A14: =IFERROR(__xludf.DUMMYFUNCTION("""COMPUTED_VALUE"""),"SKU071") -> SKU071 | B14: =IFERROR(__xludf.DUMMYFUNCTION("""COMPUTED_VALUE"""),"A") -> A | C14: =IFERROR(__xludf.DUMMYFUNCTION("""COMPUTED_VALUE"""),"N") -> N | D14: =B14&C14 -> AN | E14: =XLOOKUP(D14,$K$11:$K$19,$L$11:$L$19) -> Capital Blocked | K14: BF | L14: Regular Fast Mover
A15: =IFERROR(__xludf.DUMMYFUNCTION("""COMPUTED_VALUE"""),"SKU053") -> SKU053 | B15: =IFERROR(__xludf.DUMMYFUNCTION("""COMPUTED_VALUE"""),"A") -> A | C15: =IFERROR(__xludf.DUMMYFUNCTION("""COMPUTED_VALUE"""),"N") -> N | D15: =B15&C15 -> AN | E15: =XLOOKUP(D15,$K$11:$K$19,$L$11:$L$19) -> Capital Blocked | K15: BS | L15: Routine Stock
A16: =IFERROR(__xludf.DUMMYFUNCTION("""COMPUTED_VALUE"""),"SKU012") -> SKU012 | B16: =IFERROR(__xludf.DUMMYFUNCTION("""COMPUTED_VALUE"""),"A") -> A | C16: =IFERROR(__xludf.DUMMYFUNCTION("""COMPUTED_VALUE"""),"S") -> S | D16: =B16&C16 -> AS | E16: =XLOOKUP(D16,$K$11:$K$19,$L$11:$L$19) -> Important Item | K16: BN | L16: Slow Asset
A17: =IFERROR(__xludf.DUMMYFUNCTION("""COMPUTED_VALUE"""),"SKU089") -> SKU089 | B17: =IFERROR(__xludf.DUMMYFUNCTION("""COMPUTED_VALUE"""),"A") -> A | C17: =IFERROR(__xludf.DUMMYFUNCTION("""COMPUTED_VALUE"""),"N") -> N | D17: =B17&C17 -> AN | E17: =XLOOKUP(D17,$K$11:$K$19,$L$11:$L$19) -> Capital Blocked | K17: CF | L17: Consumable Item
A18: =IFERROR(__xludf.DUMMYFUNCTION("""COMPUTED_VALUE"""),"SKU019") -> SKU019 | B18: =IFERROR(__xludf.DUMMYFUNCTION("""COMPUTED_VALUE"""),"A") -> A | C18: =IFERROR(__xludf.DUMMYFUNCTION("""COMPUTED_VALUE"""),"S") -> S | D18: =B18&C18 -> AS | E18: =XLOOKUP(D18,$K$11:$K$19,$L$11:$L$19) -> Important Item | K18: CS | L18: Low Priority Stock
A19: =IFERROR(__xludf.DUMMYFUNCTION("""COMPUTED_VALUE"""),"SKU083") -> SKU083 | B19: =IFERROR(__xludf.DUMMYFUNCTION("""COMPUTED_VALUE"""),"A") -> A | C19: =IFERROR(__xludf.DUMMYFUNCTION("""COMPUTED_VALUE"""),"N") -> N | D19: =B19&C19 -> AN | E19: =XLOOKUP(D19,$K$11:$K$19,$L$11:$L$19) -> Capital Blocked | K19: CN | L19: Dead Stock Candidate
A20: =IFERROR(__xludf.DUMMYFUNCTION("""COMPUTED_VALUE"""),"SKU033") -> SKU033 | B20: =IFERROR(__xludf.DUMMYFUNCTION("""COMPUTED_VALUE"""),"A") -> A | C20: =IFERROR(__xludf.DUMMYFUNCTION("""COMPUTED_VALUE"""),"S") -> S | D20: =B20&C20 -> AS | E20: =XLOOKUP(D20,$K$11:$K$19,$L$11:$L$19) -> Important Item
A21: =IFERROR(__xludf.DUMMYFUNCTION("""COMPUTED_VALUE"""),"SKU002") -> SKU002 | B21: =IFERROR(__xludf.DUMMYFUNCTION("""COMPUTED_VALUE"""),"A") -> A | C21: =IFERROR(__xludf.DUMMYFUNCTION("""COMPUTED_VALUE"""),"N") -> N | D21: =B21&C21 -> AN | E21: =XLOOKUP(D21,$K$11:$K$19,$L$11:$L$19) -> Capital Blocked
A22: =IFERROR(__xludf.DUMMYFUNCTION("""COMPUTED_VALUE"""),"SKU007") -> SKU007 | B22: =IFERROR(__xludf.DUMMYFUNCTION("""COMPUTED_VALUE"""),"A") -> A | C22: =IFERROR(__xludf.DUMMYFUNCTION("""COMPUTED_VALUE"""),"N") -> N | D22: =B22&C22 -> AN | E22: =XLOOKUP(D22,$K$11:$K$19,$L$11:$L$19) -> Capital Blocked
A23: =IFERROR(__xludf.DUMMYFUNCTION("""COMPUTED_VALUE"""),"SKU039") -> SKU039 | B23: =IFERROR(__xludf.DUMMYFUNCTION("""COMPUTED_VALUE"""),"A") -> A | C23: =IFERROR(__xludf.DUMMYFUNCTION("""COMPUTED_VALUE"""),"S") -> S | D23: =B23&C23 -> AS | E23: =XLOOKUP(D23,$K$11:$K$19,$L$11:$L$19) -> Important Item
A24: =IFERROR(__xludf.DUMMYFUNCTION("""COMPUTED_VALUE"""),"SKU088") -> SKU088 | B24: =IFERROR(__xludf.DUMMYFUNCTION("""COMPUTED_VALUE"""),"A") -> A | C24: =IFERROR(__xludf.DUMMYFUNCTION("""COMPUTED_VALUE"""),"S") -> S | D24: =B24&C24 -> AS | E24: =XLOOKUP(D24,$K$11:$K$19,$L$11:$L$19) -> Important Item
A25: =IFERROR(__xludf.DUMMYFUNCTION("""COMPUTED_VALUE"""),"SKU016") -> SKU016 | B25: =IFERROR(__xludf.DUMMYFUNCTION("""COMPUTED_VALUE"""),"A") -> A | C25: =IFERROR(__xludf.DUMMYFUNCTION("""COMPUTED_VALUE"""),"S") -> S | D25: =B25&C25 -> AS | E25: =XLOOKUP(D25,$K$11:$K$19,$L$11:$L$19) -> Important Item
A26: =IFERROR(__xludf.DUMMYFUNCTION("""COMPUTED_VALUE"""),"SKU042") -> SKU042 | B26: =IFERROR(__xludf.DUMMYFUNCTION("""COMPUTED_VALUE"""),"A") -> A | C26: =IFERROR(__xludf.DUMMYFUNCTION("""COMPUTED_VALUE"""),"S") -> S | D26: =B26&C26 -> AS | E26: =XLOOKUP(D26,$K$11:$K$19,$L$11:$L$19) -> Important Item
A27: =IFERROR(__xludf.DUMMYFUNCTION("""COMPUTED_VALUE"""),"SKU060") -> SKU060 | B27: =IFERROR(__xludf.DUMMYFUNCTION("""COMPUTED_VALUE"""),"A") -> A | C27: =IFERROR(__xludf.DUMMYFUNCTION("""COMPUTED_VALUE"""),"N") -> N | D27: =B27&C27 -> AN | E27: =XLOOKUP(D27,$K$11:$K$19,$L$11:$L$19) -> Capital Blocked
A28: =IFERROR(__xludf.DUMMYFUNCTION("""COMPUTED_VALUE"""),"SKU081") -> SKU081 | B28: =IFERROR(__xludf.DUMMYFUNCTION("""COMPUTED_VALUE"""),"A") -> A | C28: =IFERROR(__xludf.DUMMYFUNCTION("""COMPUTED_VALUE"""),"F") -> F | D28: =B28&C28 -> AF | E28: =XLOOKUP(D28,$K$11:$K$19,$L$11:$L$19) -> Critical Item
A29: =IFERROR(__xludf.DUMMYFUNCTION("""COMPUTED_VALUE"""),"SKU044") -> SKU044 | B29: =IFERROR(__xludf.DUMMYFUNCTION("""COMPUTED_VALUE"""),"A") -> A | C29: =IFERROR(__xludf.DUMMYFUNCTION("""COMPUTED_VALUE"""),"N") -> N | D29: =B29&C29 -> AN | E29: =XLOOKUP(D29,$K$11:$K$19,$L$11:$L$19) -> Capital Blocked
A30: =IFERROR(__xludf.DUMMYFUNCTION("""COMPUTED_VALUE"""),"SKU045") -> SKU045 | B30: =IFERROR(__xludf.DUMMYFUNCTION("""COMPUTED_VALUE"""),"A") -> A | C30: =IFERROR(__xludf.DUMMYFUNCTION("""COMPUTED_VALUE"""),"F") -> F | D30: =B30&C30 -> AF | E30: =XLOOKUP(D30,$K$11:$K$19,$L$11:$L$19) -> Critical Item
A31: =IFERROR(__xludf.DUMMYFUNCTION("""COMPUTED_VALUE"""),"SKU078") -> SKU078 | B31: =IFERROR(__xludf.DUMMYFUNCTION("""COMPUTED_VALUE"""),"A") -> A | C31: =IFERROR(__xludf.DUMMYFUNCTION("""COMPUTED_VALUE"""),"F") -> F | D31: =B31&C31 -> AF | E31: =XLOOKUP(D31,$K$11:$K$19,$L$11:$L$19) -> Critical Item
A32: =IFERROR(__xludf.DUMMYFUNCTION("""COMPUTED_VALUE"""),"SKU029") -> SKU029 | B32: =IFERROR(__xludf.DUMMYFUNCTION("""COMPUTED_VALUE"""),"A") -> A | C32: =IFERROR(__xludf.DUMMYFUNCTION("""COMPUTED_VALUE"""),"S") -> S | D32: =B32&C32 -> AS | E32: =XLOOKUP(D32,$K$11:$K$19,$L$11:$L$19) -> Important Item
A33: =IFERROR(__xludf.DUMMYFUNCTION("""COMPUTED_VALUE"""),"SKU092") -> SKU092 | B33: =IFERROR(__xludf.DUMMYFUNCTION("""COMPUTED_VALUE"""),"A") -> A | C33: =IFERROR(__xludf.DUMMYFUNCTION("""COMPUTED_VALUE"""),"N") -> N | D33: =B33&C33 -> AN | E33: =XLOOKUP(D33,$K$11:$K$19,$L$11:$L$19) -> Capital Blocked
A34: =IFERROR(__xludf.DUMMYFUNCTION("""COMPUTED_VALUE"""),"SKU034") -> SKU034 | B34: =IFERROR(__xludf.DUMMYFUNCTION("""COMPUTED_VALUE"""),"A") -> A | C34: =IFERROR(__xludf.DUMMYFUNCTION("""COMPUTED_VALUE"""),"F") -> F | D34: =B34&C34 -> AF | E34: =XLOOKUP(D34,$K$11:$K$19,$L$11:$L$19) -> Critical Item
A35: =IFERROR(__xludf.DUMMYFUNCTION("""COMPUTED_VALUE"""),"SKU062") -> SKU062 | B35: =IFERROR(__xludf.DUMMYFUNCTION("""COMPUTED_VALUE"""),"A") -> A | C35: =IFERROR(__xludf.DUMMYFUNCTION("""COMPUTED_VALUE"""),"F") -> F | D35: =B35&C35 -> AF | E35: =XLOOKUP(D35,$K$11:$K$19,$L$11:$L$19) -> Critical Item
A36: =IFERROR(__xludf.DUMMYFUNCTION("""COMPUTED_VALUE"""),"SKU094") -> SKU094 | B36: =IFERROR(__xludf.DUMMYFUNCTION("""COMPUTED_VALUE"""),"A") -> A | C36: =IFERROR(__xludf.DUMMYFUNCTION("""COMPUTED_VALUE"""),"S") -> S | D36: =B36&C36 -> AS | E36: =XLOOKUP(D36,$K$11:$K$19,$L$11:$L$19) -> Important Item
A37: =IFERROR(__xludf.DUMMYFUNCTION("""COMPUTED_VALUE"""),"SKU041") -> SKU041 | B37: =IFERROR(__xludf.DUMMYFUNCTION("""COMPUTED_VALUE"""),"A") -> A | C37: =IFERROR(__xludf.DUMMYFUNCTION("""COMPUTED_VALUE"""),"N") -> N | D37: =B37&C37 -> AN | E37: =XLOOKUP(D37,$K$11:$K$19,$L$11:$L$19) -> Capital Blocked
A38: =IFERROR(__xludf.DUMMYFUNCTION("""COMPUTED_VALUE"""),"SKU035") -> SKU035 | B38: =IFERROR(__xludf.DUMMYFUNCTION("""COMPUTED_VALUE"""),"A") -> A | C38: =IFERROR(__xludf.DUMMYFUNCTION("""COMPUTED_VALUE"""),"S") -> S | D38: =B38&C38 -> AS | E38: =XLOOKUP(D38,$K$11:$K$19,$L$11:$L$19) -> Important Item
A39: =IFERROR(__xludf.DUMMYFUNCTION("""COMPUTED_VALUE"""),"SKU015") -> SKU015 | B39: =IFERROR(__xludf.DUMMYFUNCTION("""COMPUTED_VALUE"""),"A") -> A | C39: =IFERROR(__xludf.DUMMYFUNCTION("""COMPUTED_VALUE"""),"S") -> S | D39: =B39&C39 -> AS | E39: =XLOOKUP(D39,$K$11:$K$19,$L$11:$L$19) -> Important Item
A40: =IFERROR(__xludf.DUMMYFUNCTION("""COMPUTED_VALUE"""),"SKU075") -> SKU075 | B40: =IFERROR(__xludf.DUMMYFUNCTION("""COMPUTED_VALUE"""),"A") -> A | C40: =IFERROR(__xludf.DUMMYFUNCTION("""COMPUTED_VALUE"""),"S") -> S | D40: =B40&C40 -> AS | E40: =XLOOKUP(D40,$K$11:$K$19,$L$11:$L$19) -> Important Item
...

Sheet ABC–XYZ Matrix
A1: Item_Code | B1: ABC | C1: XYZ | D1: ABC-XYZ | E1: Interpretation
A2: SKU068 | B2: {=XLOOKUP(A2,Inventory_Data!A:A,Inventory_Data!V:V)} -> A | C2: {=XLOOKUP(A2,Inventory_Data!A:A,Inventory_Data!Z:Z)} -> Y | D2: =B2&C2 -> AY | E2: =XLOOKUP(D2,$J$8:$J$17,$K$8:$K$17) -> High value, moderate variability, monitor closely
A3: SKU003 | B3: {=XLOOKUP(A3,Inventory_Data!A:A,Inventory_Data!V:V)} -> A | C3: {=XLOOKUP(A3,Inventory_Data!A:A,Inventory_Data!Z:Z)} -> Y | D3: =B3&C3 -> AY | E3: =XLOOKUP(D3,$J$8:$J$17,$K$8:$K$17) -> High value, moderate variability, monitor closely
A4: SKU040 | B4: {=XLOOKUP(A4,Inventory_Data!A:A,Inventory_Data!V:V)} -> A | C4: {=XLOOKUP(A4,Inventory_Data!A:A,Inventory_Data!Z:Z)} -> Y | D4: =B4&C4 -> AY | E4: =XLOOKUP(D4,$J$8:$J$17,$K$8:$K$17) -> High value, moderate variability, monitor closely
A5: SKU023 | B5: {=XLOOKUP(A5,Inventory_Data!A:A,Inventory_Data!V:V)} -> A | C5: {=XLOOKUP(A5,Inventory_Data!A:A,Inventory_Data!Z:Z)} -> Y | D5: =B5&C5 -> AY | E5: =XLOOKUP(D5,$J$8:$J$17,$K$8:$K$17) -> High value, moderate variability, monitor closely
A6: SKU049 | B6: {=XLOOKUP(A6,Inventory_Data!A:A,Inventory_Data!V:V)} -> A | C6: {=XLOOKUP(A6,Inventory_Data!A:A,Inventory_Data!Z:Z)} -> Y | D6: =B6&C6 -> AY | E6: =XLOOKUP(D6,$J$8:$J$17,$K$8:$K$17) -> High value, moderate variability, monitor closely
A7: SKU030 | B7: {=XLOOKUP(A7,Inventory_Data!A:A,Inventory_Data!V:V)} -> A | C7: {=XLOOKUP(A7,Inventory_Data!A:A,Inventory_Data!Z:Z)} -> Y | D7: =B7&C7 -> AY | E7: =XLOOKUP(D7,$J$8:$J$17,$K$8:$K$17) -> High value, moderate variability, monitor closely
A8: SKU010 | B8: {=XLOOKUP(A8,Inventory_Data!A:A,Inventory_Data!V:V)} -> A | C8: {=XLOOKUP(A8,Inventory_Data!A:A,Inventory_Data!Z:Z)} -> Y | D8: =B8&C8 -> AY | E8: =XLOOKUP(D8,$J$8:$J$17,$K$8:$K$17) -> High value, moderate variability, monitor closely | J8: Category | K8: Short Interpretation
A9: SKU063 | B9: {=XLOOKUP(A9,Inventory_Data!A:A,Inventory_Data!V:V)} -> A | C9: {=XLOOKUP(A9,Inventory_Data!A:A,Inventory_Data!Z:Z)} -> Z | D9: =B9&C9 -> AZ | E9: =XLOOKUP(D9,$J$8:$J$17,$K$8:$K$17) -> High value, unpredictable demand, high planning risk | J9: AX | K9: High value, stable demand, tight control
A10: SKU067 | B10: {=XLOOKUP(A10,Inventory_Data!A:A,Inventory_Data!V:V)} -> A | C10: {=XLOOKUP(A10,Inventory_Data!A:A,Inventory_Data!Z:Z)} -> Z | D10: =B10&C10 -> AZ | E10: =XLOOKUP(D10,$J$8:$J$17,$K$8:$K$17) -> High value, unpredictable demand, high planning risk | J10: AY | K10: High value, moderate variability, monitor closely
A11: SKU048 | B11: {=XLOOKUP(A11,Inventory_Data!A:A,Inventory_Data!V:V)} -> A | C11: {=XLOOKUP(A11,Inventory_Data!A:A,Inventory_Data!Z:Z)} -> Z | D11: =B11&C11 -> AZ | E11: =XLOOKUP(D11,$J$8:$J$17,$K$8:$K$17) -> High value, unpredictable demand, high planning risk | J11: AZ | K11: High value, unpredictable demand, high planning risk
A12: SKU046 | B12: {=XLOOKUP(A12,Inventory_Data!A:A,Inventory_Data!V:V)} -> A | C12: {=XLOOKUP(A12,Inventory_Data!A:A,Inventory_Data!Z:Z)} -> Y | D12: =B12&C12 -> AY | E12: =XLOOKUP(D12,$J$8:$J$17,$K$8:$K$17) -> High value, moderate variability, monitor closely | J12: BX | K12: Medium value, stable demand, standard control
A13: SKU026 | B13: {=XLOOKUP(A13,Inventory_Data!A:A,Inventory_Data!V:V)} -> A | C13: {=XLOOKUP(A13,Inventory_Data!A:A,Inventory_Data!Z:Z)} -> Z | D13: =B13&C13 -> AZ | E13: =XLOOKUP(D13,$J$8:$J$17,$K$8:$K$17) -> High value, unpredictable demand, high planning risk | J13: BY | K13: Medium value, moderate variability, regular review
A14: SKU071 | B14: {=XLOOKUP(A14,Inventory_Data!A:A,Inventory_Data!V:V)} -> A | C14: {=XLOOKUP(A14,Inventory_Data!A:A,Inventory_Data!Z:Z)} -> Z | D14: =B14&C14 -> AZ | E14: =XLOOKUP(D14,$J$8:$J$17,$K$8:$K$17) -> High value, unpredictable demand, high planning risk | J14: BZ | K14: Medium value, erratic demand, monitor stock levels
A15: SKU053 | B15: {=XLOOKUP(A15,Inventory_Data!A:A,Inventory_Data!V:V)} -> A | C15: {=XLOOKUP(A15,Inventory_Data!A:A,Inventory_Data!Z:Z)} -> Z | D15: =B15&C15 -> AZ | E15: =XLOOKUP(D15,$J$8:$J$17,$K$8:$K$17) -> High value, unpredictable demand, high planning risk | J15: CX | K15: Low value, stable demand, automate replenishment
A16: SKU012 | B16: {=XLOOKUP(A16,Inventory_Data!A:A,Inventory_Data!V:V)} -> A | C16: {=XLOOKUP(A16,Inventory_Data!A:A,Inventory_Data!Z:Z)} -> Y | D16: =B16&C16 -> AY | E16: =XLOOKUP(D16,$J$8:$J$17,$K$8:$K$17) -> High value, moderate variability, monitor closely | J16: CY | K16: Low value, moderate variability, simple monitoring
A17: SKU089 | B17: {=XLOOKUP(A17,Inventory_Data!A:A,Inventory_Data!V:V)} -> A | C17: {=XLOOKUP(A17,Inventory_Data!A:A,Inventory_Data!Z:Z)} -> Z | D17: =B17&C17 -> AZ | E17: =XLOOKUP(D17,$J$8:$J$17,$K$8:$K$17) -> High value, unpredictable demand, high planning risk | J17: CZ | K17: Low value, erratic demand, review for obsolescence
A18: SKU019 | B18: {=XLOOKUP(A18,Inventory_Data!A:A,Inventory_Data!V:V)} -> A | C18: {=XLOOKUP(A18,Inventory_Data!A:A,Inventory_Data!Z:Z)} -> Z | D18: =B18&C18 -> AZ | E18: =XLOOKUP(D18,$J$8:$J$17,$K$8:$K$17) -> High value, unpredictable demand, high planning risk
A19: SKU083 | B19: {=XLOOKUP(A19,Inventory_Data!A:A,Inventory_Data!V:V)} -> A | C19: {=XLOOKUP(A19,Inventory_Data!A:A,Inventory_Data!Z:Z)} -> Z | D19: =B19&C19 -> AZ | E19: =XLOOKUP(D19,$J$8:$J$17,$K$8:$K$17) -> High value, unpredictable demand, high planning risk
A20: SKU033 | B20: {=XLOOKUP(A20,Inventory_Data!A:A,Inventory_Data!V:V)} -> A | C20: {=XLOOKUP(A20,Inventory_Data!A:A,Inventory_Data!Z:Z)} -> Y | D20: =B20&C20 -> AY | E20: =XLOOKUP(D20,$J$8:$J$17,$K$8:$K$17) -> High value, moderate variability, monitor closely
A21: SKU002 | B21: {=XLOOKUP(A21,Inventory_Data!A:A,Inventory_Data!V:V)} -> A | C21: {=XLOOKUP(A21,Inventory_Data!A:A,Inventory_Data!Z:Z)} -> Z | D21: =B21&C21 -> AZ | E21: =XLOOKUP(D21,$J$8:$J$17,$K$8:$K$17) -> High value, unpredictable demand, high planning risk
A22: SKU007 | B22: {=XLOOKUP(A22,Inventory_Data!A:A,Inventory_Data!V:V)} -> A | C22: {=XLOOKUP(A22,Inventory_Data!A:A,Inventory_Data!Z:Z)} -> Z | D22: =B22&C22 -> AZ | E22: =XLOOKUP(D22,$J$8:$J$17,$K$8:$K$17) -> High value, unpredictable demand, high planning risk
A23: SKU039 | B23: {=XLOOKUP(A23,Inventory_Data!A:A,Inventory_Data!V:V)} -> A | C23: {=XLOOKUP(A23,Inventory_Data!A:A,Inventory_Data!Z:Z)} -> Z | D23: =B23&C23 -> AZ | E23: =XLOOKUP(D23,$J$8:$J$17,$K$8:$K$17) -> High value, unpredictable demand, high planning risk
A24: SKU088 | B24: {=XLOOKUP(A24,Inventory_Data!A:A,Inventory_Data!V:V)} -> A | C24: {=XLOOKUP(A24,Inventory_Data!A:A,Inventory_Data!Z:Z)} -> Z | D24: =B24&C24 -> AZ | E24: =XLOOKUP(D24,$J$8:$J$17,$K$8:$K$17) -> High value, unpredictable demand, high planning risk
A25: SKU016 | B25: {=XLOOKUP(A25,Inventory_Data!A:A,Inventory_Data!V:V)} -> A | C25: {=XLOOKUP(A25,Inventory_Data!A:A,Inventory_Data!Z:Z)} -> Z | D25: =B25&C25 -> AZ | E25: =XLOOKUP(D25,$J$8:$J$17,$K$8:$K$17) -> High value, unpredictable demand, high planning risk
A26: SKU042 | B26: {=XLOOKUP(A26,Inventory_Data!A:A,Inventory_Data!V:V)} -> A | C26: {=XLOOKUP(A26,Inventory_Data!A:A,Inventory_Data!Z:Z)} -> Z | D26: =B26&C26 -> AZ | E26: =XLOOKUP(D26,$J$8:$J$17,$K$8:$K$17) -> High value, unpredictable demand, high planning risk
A27: SKU060 | B27: {=XLOOKUP(A27,Inventory_Data!A:A,Inventory_Data!V:V)} -> A | C27: {=XLOOKUP(A27,Inventory_Data!A:A,Inventory_Data!Z:Z)} -> Y | D27: =B27&C27 -> AY | E27: =XLOOKUP(D27,$J$8:$J$17,$K$8:$K$17) -> High value, moderate variability, monitor closely
A28: SKU081 | B28: {=XLOOKUP(A28,Inventory_Data!A:A,Inventory_Data!V:V)} -> A | C28: {=XLOOKUP(A28,Inventory_Data!A:A,Inventory_Data!Z:Z)} -> Y | D28: =B28&C28 -> AY | E28: =XLOOKUP(D28,$J$8:$J$17,$K$8:$K$17) -> High value, moderate variability, monitor closely
A29: SKU044 | B29: {=XLOOKUP(A29,Inventory_Data!A:A,Inventory_Data!V:V)} -> A | C29: {=XLOOKUP(A29,Inventory_Data!A:A,Inventory_Data!Z:Z)} -> Z | D29: =B29&C29 -> AZ | E29: =XLOOKUP(D29,$J$8:$J$17,$K$8:$K$17) -> High value, unpredictable demand, high planning risk
... A101: SKU084 | B101: {=XLOOKUP(A101,Inventory_Data!A:A,Inventory_Data!V:V)} -> C | C101: {=XLOOKUP(A101,Inventory_Data!A:A,Inventory_Data!Z:Z)} -> Y | D101: =B101&C101 -> CY | E101: =XLOOKUP(D101,$J$8:$J$17,$K$8:$K$17) -> Low value, moderate variability, simple monitoring

Sheet ABC_XYZ Interpretation
A11: Category | B11: Short Interpretation
A12: AX | B12: High value, stable demand, tight control
A13: AY | B13: High value, moderate variability, monitor closely
A14: AZ | B14: High value, unpredictable demand, high planning risk
A15: BX | B15: Medium value, stable demand, standard control
A16: BY | B16: Medium value, moderate variability, regular review
A17: BZ | B17: Medium value, erratic demand, monitor stock levels
A18: CX | B18: Low value, stable demand, automate replenishment
A19: CY | B19: Low value, moderate variability, simple monitoring
A20: CZ | B20: Low value, erratic demand, review for obsolescence

Sheet ABC_FSN Matrix
D3: Category | E3: Meaning
D4: AF | E4: Critical Item
D5: AS | E5: Important Item
D6: AN | E6: Capital Blocked
D7: BF | E7: Regular Fast Mover
D8: BS | E8: Routine Stock
D9: BN | E9: Slow Asset
D10: CF | E10: Consumable Item
D11: CS | E11: Low Priority Stock
D12: CN | E12: Dead Stock Candidate
